Internal Server Error: /api/inventory/
Traceback (most recent call last):
  File "C:\Users\USER\AppData\Local\Programs\Python\Python313\Lib\site-packages\rest_framework\views.py", line 497, in dispatch
    self.initial(request, *args, **kwargs)
    ~~~~~~~~~~~~^^^^^^^^^^^^^^^^^^^^^^^^^^
  File "C:\Users\USER\AppData\Local\Programs\Python\Python313\Lib\site-packages\rest_framework\views.py", line 415, in initial
    self.check_permissions(request)
    ~~~~~~~~~~~~~~~~~~~~~~^^^^^^^^^
  File "C:\Users\USER\AppData\Local\Programs\Python\Python313\Lib\site-packages\rest_framework\views.py", line 333, in check_permissions
    self.permission_denied(
    ~~~~~~~~~~~~~~~~~~~~~~^
        request,
        ^^^^^^^^
        message=getattr(permission, 'message', None),
        ^^^^^^^^^^^^^^^^^^^^^^^^^^^^^^^^^^^^^^^^^^^^^
        code=getattr(permission, 'code', None)
        ^^^^^^^^^^^^^^^^^^^^^^^^^^^^^^^^^^^^^^
    )
    ^
  File "C:\Users\USER\AppData\Local\Programs\Python\Python313\Lib\site-packages\rest_framework\views.py", line 174, in permission_denied
    raise exceptions.NotAuthenticated()
rest_framework.exceptions.NotAuthenticated: Authentication credentials were not provided.

During handling of the above exception, another exception occurred:

Traceback (most recent call last):
  File "C:\Users\USER\AppData\Local\Programs\Python\Python313\Lib\site-packages\django\utils\module_loading.py", line 30, in import_string
    return cached_import(module_path, class_name)
  File "C:\Users\USER\AppData\Local\Programs\Python\Python313\Lib\site-packages\django\utils\module_loading.py", line 16, in cached_import
    return getattr(module, class_name)
AttributeError: module 'inventory_automation.middleware' has no attribute 'custom_exception_handler'

The above exception was the direct cause of the following exception:

Traceback (most recent call last):
  File "C:\Users\USER\AppData\Local\Programs\Python\Python313\Lib\site-packages\rest_framework\settings.py", line 179, in import_from_string
    return import_string(val)
  File "C:\Users\USER\AppData\Local\Programs\Python\Python313\Lib\site-packages\django\utils\module_loading.py", line 32, in import_string
    raise ImportError(
    ...<2 lines>...
    ) from err
ImportError: Module "inventory_automation.middleware" does not define a "custom_exception_handler" attribute/class

During handling of the above exception, another exception occurred:

Traceback (most recent call last):
  File "C:\Users\USER\AppData\Local\Programs\Python\Python313\Lib\site-packages\django\core\handlers\exception.py", line 55, in inner
    response = get_response(request)
  File "C:\Users\USER\AppData\Local\Programs\Python\Python313\Lib\site-packages\django\core\handlers\base.py", line 197, in _get_response
    response = wrapped_callback(request, *callback_args, **callback_kwargs)
  File "C:\Users\USER\AppData\Local\Programs\Python\Python313\Lib\site-packages\django\views\decorators\csrf.py", line 65, in _view_wrapper
    return view_func(request, *args, **kwargs)
  File "C:\Users\USER\AppData\Local\Programs\Python\Python313\Lib\site-packages\rest_framework\viewsets.py", line 124, in view
    return self.dispatch(request, *args, **kwargs)
           ~~~~~~~~~~~~~^^^^^^^^^^^^^^^^^^^^^^^^^^
  File "C:\Users\USER\AppData\Local\Programs\Python\Python313\Lib\site-packages\rest_framework\views.py", line 509, in dispatch
    response = self.handle_exception(exc)
  File "C:\Users\USER\AppData\Local\Programs\Python\Python313\Lib\site-packages\rest_framework\views.py", line 463, in handle_exception
    exception_handler = self.get_exception_handler()
  File "C:\Users\USER\AppData\Local\Programs\Python\Python313\Lib\site-packages\rest_framework\views.py", line 298, in get_exception_handler
    return self.settings.EXCEPTION_HANDLER
           ^^^^^^^^^^^^^^^^^^^^^^^^^^^^^^^
  File "C:\Users\USER\AppData\Local\Programs\Python\Python313\Lib\site-packages\rest_framework\settings.py", line 227, in __getattr__
    val = perform_import(val, attr)
  File "C:\Users\USER\AppData\Local\Programs\Python\Python313\Lib\site-packages\rest_framework\settings.py", line 168, in perform_import
    return import_from_string(val, setting_name)
  File "C:\Users\USER\AppData\Local\Programs\Python\Python313\Lib\site-packages\rest_framework\settings.py", line 182, in import_from_string
    raise ImportError(msg)
ImportError: Could not import 'inventory_automation.middleware.custom_exception_handler' for API setting 'EXCEPTION_HANDLER'. ImportError: Module "inventory_automation.middleware" does not define a "custom_exception_handler" attribute/class.
"GET /api/inventory/ HTTP/1.1" 500 138853
Internal Server Error: /api/inventory/
Traceback (most recent call last):
  File "C:\Users\USER\AppData\Local\Programs\Python\Python313\Lib\site-packages\rest_framework\views.py", line 497, in dispatch
    self.initial(request, *args, **kwargs)
    ~~~~~~~~~~~~^^^^^^^^^^^^^^^^^^^^^^^^^^
  File "C:\Users\USER\AppData\Local\Programs\Python\Python313\Lib\site-packages\rest_framework\views.py", line 415, in initial
    self.check_permissions(request)
    ~~~~~~~~~~~~~~~~~~~~~~^^^^^^^^^
  File "C:\Users\USER\AppData\Local\Programs\Python\Python313\Lib\site-packages\rest_framework\views.py", line 333, in check_permissions
    self.permission_denied(
    ~~~~~~~~~~~~~~~~~~~~~~^
        request,
        ^^^^^^^^
        message=getattr(permission, 'message', None),
        ^^^^^^^^^^^^^^^^^^^^^^^^^^^^^^^^^^^^^^^^^^^^^
        code=getattr(permission, 'code', None)
        ^^^^^^^^^^^^^^^^^^^^^^^^^^^^^^^^^^^^^^
    )
    ^
  File "C:\Users\USER\AppData\Local\Programs\Python\Python313\Lib\site-packages\rest_framework\views.py", line 174, in permission_denied
    raise exceptions.NotAuthenticated()
rest_framework.exceptions.NotAuthenticated: Authentication credentials were not provided.

During handling of the above exception, another exception occurred:

Traceback (most recent call last):
  File "C:\Users\USER\AppData\Local\Programs\Python\Python313\Lib\site-packages\django\utils\module_loading.py", line 30, in import_string
    return cached_import(module_path, class_name)
  File "C:\Users\USER\AppData\Local\Programs\Python\Python313\Lib\site-packages\django\utils\module_loading.py", line 16, in cached_import
    return getattr(module, class_name)
AttributeError: module 'inventory_automation.middleware' has no attribute 'custom_exception_handler'

The above exception was the direct cause of the following exception:

Traceback (most recent call last):
  File "C:\Users\USER\AppData\Local\Programs\Python\Python313\Lib\site-packages\rest_framework\settings.py", line 179, in import_from_string
    return import_string(val)
  File "C:\Users\USER\AppData\Local\Programs\Python\Python313\Lib\site-packages\django\utils\module_loading.py", line 32, in import_string
    raise ImportError(
    ...<2 lines>...
    ) from err
ImportError: Module "inventory_automation.middleware" does not define a "custom_exception_handler" attribute/class

During handling of the above exception, another exception occurred:

Traceback (most recent call last):
  File "C:\Users\USER\AppData\Local\Programs\Python\Python313\Lib\site-packages\django\core\handlers\exception.py", line 55, in inner
    response = get_response(request)
  File "C:\Users\USER\AppData\Local\Programs\Python\Python313\Lib\site-packages\django\core\handlers\base.py", line 197, in _get_response
    response = wrapped_callback(request, *callback_args, **callback_kwargs)
  File "C:\Users\USER\AppData\Local\Programs\Python\Python313\Lib\site-packages\django\views\decorators\csrf.py", line 65, in _view_wrapper
    return view_func(request, *args, **kwargs)
  File "C:\Users\USER\AppData\Local\Programs\Python\Python313\Lib\site-packages\rest_framework\viewsets.py", line 124, in view
    return self.dispatch(request, *args, **kwargs)
           ~~~~~~~~~~~~~^^^^^^^^^^^^^^^^^^^^^^^^^^
  File "C:\Users\USER\AppData\Local\Programs\Python\Python313\Lib\site-packages\rest_framework\views.py", line 509, in dispatch
    response = self.handle_exception(exc)
  File "C:\Users\USER\AppData\Local\Programs\Python\Python313\Lib\site-packages\rest_framework\views.py", line 463, in handle_exception
    exception_handler = self.get_exception_handler()
  File "C:\Users\USER\AppData\Local\Programs\Python\Python313\Lib\site-packages\rest_framework\views.py", line 298, in get_exception_handler
    return self.settings.EXCEPTION_HANDLER
           ^^^^^^^^^^^^^^^^^^^^^^^^^^^^^^^
  File "C:\Users\USER\AppData\Local\Programs\Python\Python313\Lib\site-packages\rest_framework\settings.py", line 227, in __getattr__
    val = perform_import(val, attr)
  File "C:\Users\USER\AppData\Local\Programs\Python\Python313\Lib\site-packages\rest_framework\settings.py", line 168, in perform_import
    return import_from_string(val, setting_name)
  File "C:\Users\USER\AppData\Local\Programs\Python\Python313\Lib\site-packages\rest_framework\settings.py", line 182, in import_from_string
    raise ImportError(msg)
ImportError: Could not import 'inventory_automation.middleware.custom_exception_handler' for API setting 'EXCEPTION_HANDLER'. ImportError: Module "inventory_automation.middleware" does not define a "custom_exception_handler" attribute/class.
"GET /api/inventory/ HTTP/1.1" 500 138853
Internal Server Error: /api/inventory/
Traceback (most recent call last):
  File "C:\Users\USER\AppData\Local\Programs\Python\Python313\Lib\site-packages\rest_framework\views.py", line 497, in dispatch
    self.initial(request, *args, **kwargs)
    ~~~~~~~~~~~~^^^^^^^^^^^^^^^^^^^^^^^^^^
  File "C:\Users\USER\AppData\Local\Programs\Python\Python313\Lib\site-packages\rest_framework\views.py", line 415, in initial
    self.check_permissions(request)
    ~~~~~~~~~~~~~~~~~~~~~~^^^^^^^^^
  File "C:\Users\USER\AppData\Local\Programs\Python\Python313\Lib\site-packages\rest_framework\views.py", line 333, in check_permissions
    self.permission_denied(
    ~~~~~~~~~~~~~~~~~~~~~~^
        request,
        ^^^^^^^^
        message=getattr(permission, 'message', None),
        ^^^^^^^^^^^^^^^^^^^^^^^^^^^^^^^^^^^^^^^^^^^^^
        code=getattr(permission, 'code', None)
        ^^^^^^^^^^^^^^^^^^^^^^^^^^^^^^^^^^^^^^
    )
    ^
  File "C:\Users\USER\AppData\Local\Programs\Python\Python313\Lib\site-packages\rest_framework\views.py", line 174, in permission_denied
    raise exceptions.NotAuthenticated()
rest_framework.exceptions.NotAuthenticated: Authentication credentials were not provided.

During handling of the above exception, another exception occurred:

Traceback (most recent call last):
  File "C:\Users\USER\AppData\Local\Programs\Python\Python313\Lib\site-packages\django\utils\module_loading.py", line 30, in import_string
    return cached_import(module_path, class_name)
  File "C:\Users\USER\AppData\Local\Programs\Python\Python313\Lib\site-packages\django\utils\module_loading.py", line 16, in cached_import
    return getattr(module, class_name)
AttributeError: module 'inventory_automation.middleware' has no attribute 'custom_exception_handler'

The above exception was the direct cause of the following exception:

Traceback (most recent call last):
  File "C:\Users\USER\AppData\Local\Programs\Python\Python313\Lib\site-packages\rest_framework\settings.py", line 179, in import_from_string
    return import_string(val)
  File "C:\Users\USER\AppData\Local\Programs\Python\Python313\Lib\site-packages\django\utils\module_loading.py", line 32, in import_string
    raise ImportError(
    ...<2 lines>...
    ) from err
ImportError: Module "inventory_automation.middleware" does not define a "custom_exception_handler" attribute/class

During handling of the above exception, another exception occurred:

Traceback (most recent call last):
  File "C:\Users\USER\AppData\Local\Programs\Python\Python313\Lib\site-packages\django\core\handlers\exception.py", line 55, in inner
    response = get_response(request)
  File "C:\Users\USER\AppData\Local\Programs\Python\Python313\Lib\site-packages\django\core\handlers\base.py", line 197, in _get_response
    response = wrapped_callback(request, *callback_args, **callback_kwargs)
  File "C:\Users\USER\AppData\Local\Programs\Python\Python313\Lib\site-packages\django\views\decorators\csrf.py", line 65, in _view_wrapper
    return view_func(request, *args, **kwargs)
  File "C:\Users\USER\AppData\Local\Programs\Python\Python313\Lib\site-packages\rest_framework\viewsets.py", line 124, in view
    return self.dispatch(request, *args, **kwargs)
           ~~~~~~~~~~~~~^^^^^^^^^^^^^^^^^^^^^^^^^^
  File "C:\Users\USER\AppData\Local\Programs\Python\Python313\Lib\site-packages\rest_framework\views.py", line 509, in dispatch
    response = self.handle_exception(exc)
  File "C:\Users\USER\AppData\Local\Programs\Python\Python313\Lib\site-packages\rest_framework\views.py", line 463, in handle_exception
    exception_handler = self.get_exception_handler()
  File "C:\Users\USER\AppData\Local\Programs\Python\Python313\Lib\site-packages\rest_framework\views.py", line 298, in get_exception_handler
    return self.settings.EXCEPTION_HANDLER
           ^^^^^^^^^^^^^^^^^^^^^^^^^^^^^^^
  File "C:\Users\USER\AppData\Local\Programs\Python\Python313\Lib\site-packages\rest_framework\settings.py", line 227, in __getattr__
    val = perform_import(val, attr)
  File "C:\Users\USER\AppData\Local\Programs\Python\Python313\Lib\site-packages\rest_framework\settings.py", line 168, in perform_import
    return import_from_string(val, setting_name)
  File "C:\Users\USER\AppData\Local\Programs\Python\Python313\Lib\site-packages\rest_framework\settings.py", line 182, in import_from_string
    raise ImportError(msg)
ImportError: Could not import 'inventory_automation.middleware.custom_exception_handler' for API setting 'EXCEPTION_HANDLER'. ImportError: Module "inventory_automation.middleware" does not define a "custom_exception_handler" attribute/class.
"GET /api/inventory/ HTTP/1.1" 500 138853
Internal Server Error: /api/inventory/
Traceback (most recent call last):
  File "C:\Users\USER\AppData\Local\Programs\Python\Python313\Lib\site-packages\rest_framework\views.py", line 497, in dispatch
    self.initial(request, *args, **kwargs)
    ~~~~~~~~~~~~^^^^^^^^^^^^^^^^^^^^^^^^^^
  File "C:\Users\USER\AppData\Local\Programs\Python\Python313\Lib\site-packages\rest_framework\views.py", line 415, in initial
    self.check_permissions(request)
    ~~~~~~~~~~~~~~~~~~~~~~^^^^^^^^^
  File "C:\Users\USER\AppData\Local\Programs\Python\Python313\Lib\site-packages\rest_framework\views.py", line 333, in check_permissions
    self.permission_denied(
    ~~~~~~~~~~~~~~~~~~~~~~^
        request,
        ^^^^^^^^
        message=getattr(permission, 'message', None),
        ^^^^^^^^^^^^^^^^^^^^^^^^^^^^^^^^^^^^^^^^^^^^^
        code=getattr(permission, 'code', None)
        ^^^^^^^^^^^^^^^^^^^^^^^^^^^^^^^^^^^^^^
    )
    ^
  File "C:\Users\USER\AppData\Local\Programs\Python\Python313\Lib\site-packages\rest_framework\views.py", line 174, in permission_denied
    raise exceptions.NotAuthenticated()
rest_framework.exceptions.NotAuthenticated: Authentication credentials were not provided.

During handling of the above exception, another exception occurred:

Traceback (most recent call last):
  File "C:\Users\USER\AppData\Local\Programs\Python\Python313\Lib\site-packages\django\utils\module_loading.py", line 30, in import_string
    return cached_import(module_path, class_name)
  File "C:\Users\USER\AppData\Local\Programs\Python\Python313\Lib\site-packages\django\utils\module_loading.py", line 16, in cached_import
    return getattr(module, class_name)
AttributeError: module 'inventory_automation.middleware' has no attribute 'custom_exception_handler'

The above exception was the direct cause of the following exception:

Traceback (most recent call last):
  File "C:\Users\USER\AppData\Local\Programs\Python\Python313\Lib\site-packages\rest_framework\settings.py", line 179, in import_from_string
    return import_string(val)
  File "C:\Users\USER\AppData\Local\Programs\Python\Python313\Lib\site-packages\django\utils\module_loading.py", line 32, in import_string
    raise ImportError(
    ...<2 lines>...
    ) from err
ImportError: Module "inventory_automation.middleware" does not define a "custom_exception_handler" attribute/class

During handling of the above exception, another exception occurred:

Traceback (most recent call last):
  File "C:\Users\USER\AppData\Local\Programs\Python\Python313\Lib\site-packages\django\core\handlers\exception.py", line 55, in inner
    response = get_response(request)
  File "C:\Users\USER\AppData\Local\Programs\Python\Python313\Lib\site-packages\django\core\handlers\base.py", line 197, in _get_response
    response = wrapped_callback(request, *callback_args, **callback_kwargs)
  File "C:\Users\USER\AppData\Local\Programs\Python\Python313\Lib\site-packages\django\views\decorators\csrf.py", line 65, in _view_wrapper
    return view_func(request, *args, **kwargs)
  File "C:\Users\USER\AppData\Local\Programs\Python\Python313\Lib\site-packages\rest_framework\viewsets.py", line 124, in view
    return self.dispatch(request, *args, **kwargs)
           ~~~~~~~~~~~~~^^^^^^^^^^^^^^^^^^^^^^^^^^
  File "C:\Users\USER\AppData\Local\Programs\Python\Python313\Lib\site-packages\rest_framework\views.py", line 509, in dispatch
    response = self.handle_exception(exc)
  File "C:\Users\USER\AppData\Local\Programs\Python\Python313\Lib\site-packages\rest_framework\views.py", line 463, in handle_exception
    exception_handler = self.get_exception_handler()
  File "C:\Users\USER\AppData\Local\Programs\Python\Python313\Lib\site-packages\rest_framework\views.py", line 298, in get_exception_handler
    return self.settings.EXCEPTION_HANDLER
           ^^^^^^^^^^^^^^^^^^^^^^^^^^^^^^^
  File "C:\Users\USER\AppData\Local\Programs\Python\Python313\Lib\site-packages\rest_framework\settings.py", line 227, in __getattr__
    val = perform_import(val, attr)
  File "C:\Users\USER\AppData\Local\Programs\Python\Python313\Lib\site-packages\rest_framework\settings.py", line 168, in perform_import
    return import_from_string(val, setting_name)
  File "C:\Users\USER\AppData\Local\Programs\Python\Python313\Lib\site-packages\rest_framework\settings.py", line 182, in import_from_string
    raise ImportError(msg)
ImportError: Could not import 'inventory_automation.middleware.custom_exception_handler' for API setting 'EXCEPTION_HANDLER'. ImportError: Module "inventory_automation.middleware" does not define a "custom_exception_handler" attribute/class.
"GET /api/inventory/ HTTP/1.1" 500 138853
Internal Server Error: /api/inventory/
Traceback (most recent call last):
  File "C:\Users\USER\AppData\Local\Programs\Python\Python313\Lib\site-packages\rest_framework\views.py", line 497, in dispatch
    self.initial(request, *args, **kwargs)
    ~~~~~~~~~~~~^^^^^^^^^^^^^^^^^^^^^^^^^^
  File "C:\Users\USER\AppData\Local\Programs\Python\Python313\Lib\site-packages\rest_framework\views.py", line 415, in initial
    self.check_permissions(request)
    ~~~~~~~~~~~~~~~~~~~~~~^^^^^^^^^
  File "C:\Users\USER\AppData\Local\Programs\Python\Python313\Lib\site-packages\rest_framework\views.py", line 333, in check_permissions
    self.permission_denied(
    ~~~~~~~~~~~~~~~~~~~~~~^
        request,
        ^^^^^^^^
        message=getattr(permission, 'message', None),
        ^^^^^^^^^^^^^^^^^^^^^^^^^^^^^^^^^^^^^^^^^^^^^
        code=getattr(permission, 'code', None)
        ^^^^^^^^^^^^^^^^^^^^^^^^^^^^^^^^^^^^^^
    )
    ^
  File "C:\Users\USER\AppData\Local\Programs\Python\Python313\Lib\site-packages\rest_framework\views.py", line 174, in permission_denied
    raise exceptions.NotAuthenticated()
rest_framework.exceptions.NotAuthenticated: Authentication credentials were not provided.

During handling of the above exception, another exception occurred:

Traceback (most recent call last):
  File "C:\Users\USER\AppData\Local\Programs\Python\Python313\Lib\site-packages\django\utils\module_loading.py", line 30, in import_string
    return cached_import(module_path, class_name)
  File "C:\Users\USER\AppData\Local\Programs\Python\Python313\Lib\site-packages\django\utils\module_loading.py", line 16, in cached_import
    return getattr(module, class_name)
AttributeError: module 'inventory_automation.middleware' has no attribute 'custom_exception_handler'

The above exception was the direct cause of the following exception:

Traceback (most recent call last):
  File "C:\Users\USER\AppData\Local\Programs\Python\Python313\Lib\site-packages\rest_framework\settings.py", line 179, in import_from_string
    return import_string(val)
  File "C:\Users\USER\AppData\Local\Programs\Python\Python313\Lib\site-packages\django\utils\module_loading.py", line 32, in import_string
    raise ImportError(
    ...<2 lines>...
    ) from err
ImportError: Module "inventory_automation.middleware" does not define a "custom_exception_handler" attribute/class

During handling of the above exception, another exception occurred:

Traceback (most recent call last):
  File "C:\Users\USER\AppData\Local\Programs\Python\Python313\Lib\site-packages\django\core\handlers\exception.py", line 55, in inner
    response = get_response(request)
  File "C:\Users\USER\AppData\Local\Programs\Python\Python313\Lib\site-packages\django\core\handlers\base.py", line 197, in _get_response
    response = wrapped_callback(request, *callback_args, **callback_kwargs)
  File "C:\Users\USER\AppData\Local\Programs\Python\Python313\Lib\site-packages\django\views\decorators\csrf.py", line 65, in _view_wrapper
    return view_func(request, *args, **kwargs)
  File "C:\Users\USER\AppData\Local\Programs\Python\Python313\Lib\site-packages\rest_framework\viewsets.py", line 124, in view
    return self.dispatch(request, *args, **kwargs)
           ~~~~~~~~~~~~~^^^^^^^^^^^^^^^^^^^^^^^^^^
  File "C:\Users\USER\AppData\Local\Programs\Python\Python313\Lib\site-packages\rest_framework\views.py", line 509, in dispatch
    response = self.handle_exception(exc)
  File "C:\Users\USER\AppData\Local\Programs\Python\Python313\Lib\site-packages\rest_framework\views.py", line 463, in handle_exception
    exception_handler = self.get_exception_handler()
  File "C:\Users\USER\AppData\Local\Programs\Python\Python313\Lib\site-packages\rest_framework\views.py", line 298, in get_exception_handler
    return self.settings.EXCEPTION_HANDLER
           ^^^^^^^^^^^^^^^^^^^^^^^^^^^^^^^
  File "C:\Users\USER\AppData\Local\Programs\Python\Python313\Lib\site-packages\rest_framework\settings.py", line 227, in __getattr__
    val = perform_import(val, attr)
  File "C:\Users\USER\AppData\Local\Programs\Python\Python313\Lib\site-packages\rest_framework\settings.py", line 168, in perform_import
    return import_from_string(val, setting_name)
  File "C:\Users\USER\AppData\Local\Programs\Python\Python313\Lib\site-packages\rest_framework\settings.py", line 182, in import_from_string
    raise ImportError(msg)
ImportError: Could not import 'inventory_automation.middleware.custom_exception_handler' for API setting 'EXCEPTION_HANDLER'. ImportError: Module "inventory_automation.middleware" does not define a "custom_exception_handler" attribute/class.
"GET /api/inventory/ HTTP/1.1" 500 138853
Internal Server Error: /api/inventory/
Traceback (most recent call last):
  File "C:\Users\USER\AppData\Local\Programs\Python\Python313\Lib\site-packages\rest_framework\views.py", line 497, in dispatch
    self.initial(request, *args, **kwargs)
    ~~~~~~~~~~~~^^^^^^^^^^^^^^^^^^^^^^^^^^
  File "C:\Users\USER\AppData\Local\Programs\Python\Python313\Lib\site-packages\rest_framework\views.py", line 415, in initial
    self.check_permissions(request)
    ~~~~~~~~~~~~~~~~~~~~~~^^^^^^^^^
  File "C:\Users\USER\AppData\Local\Programs\Python\Python313\Lib\site-packages\rest_framework\views.py", line 333, in check_permissions
    self.permission_denied(
    ~~~~~~~~~~~~~~~~~~~~~~^
        request,
        ^^^^^^^^
        message=getattr(permission, 'message', None),
        ^^^^^^^^^^^^^^^^^^^^^^^^^^^^^^^^^^^^^^^^^^^^^
        code=getattr(permission, 'code', None)
        ^^^^^^^^^^^^^^^^^^^^^^^^^^^^^^^^^^^^^^
    )
    ^
  File "C:\Users\USER\AppData\Local\Programs\Python\Python313\Lib\site-packages\rest_framework\views.py", line 174, in permission_denied
    raise exceptions.NotAuthenticated()
rest_framework.exceptions.NotAuthenticated: Authentication credentials were not provided.

During handling of the above exception, another exception occurred:

Traceback (most recent call last):
  File "C:\Users\USER\AppData\Local\Programs\Python\Python313\Lib\site-packages\django\utils\module_loading.py", line 30, in import_string
    return cached_import(module_path, class_name)
  File "C:\Users\USER\AppData\Local\Programs\Python\Python313\Lib\site-packages\django\utils\module_loading.py", line 16, in cached_import
    return getattr(module, class_name)
AttributeError: module 'inventory_automation.middleware' has no attribute 'custom_exception_handler'

The above exception was the direct cause of the following exception:

Traceback (most recent call last):
  File "C:\Users\USER\AppData\Local\Programs\Python\Python313\Lib\site-packages\rest_framework\settings.py", line 179, in import_from_string
    return import_string(val)
  File "C:\Users\USER\AppData\Local\Programs\Python\Python313\Lib\site-packages\django\utils\module_loading.py", line 32, in import_string
    raise ImportError(
    ...<2 lines>...
    ) from err
ImportError: Module "inventory_automation.middleware" does not define a "custom_exception_handler" attribute/class

During handling of the above exception, another exception occurred:

Traceback (most recent call last):
  File "C:\Users\USER\AppData\Local\Programs\Python\Python313\Lib\site-packages\django\core\handlers\exception.py", line 55, in inner
    response = get_response(request)
  File "C:\Users\USER\AppData\Local\Programs\Python\Python313\Lib\site-packages\django\core\handlers\base.py", line 197, in _get_response
    response = wrapped_callback(request, *callback_args, **callback_kwargs)
  File "C:\Users\USER\AppData\Local\Programs\Python\Python313\Lib\site-packages\django\views\decorators\csrf.py", line 65, in _view_wrapper
    return view_func(request, *args, **kwargs)
  File "C:\Users\USER\AppData\Local\Programs\Python\Python313\Lib\site-packages\rest_framework\viewsets.py", line 124, in view
    return self.dispatch(request, *args, **kwargs)
           ~~~~~~~~~~~~~^^^^^^^^^^^^^^^^^^^^^^^^^^
  File "C:\Users\USER\AppData\Local\Programs\Python\Python313\Lib\site-packages\rest_framework\views.py", line 509, in dispatch
    response = self.handle_exception(exc)
  File "C:\Users\USER\AppData\Local\Programs\Python\Python313\Lib\site-packages\rest_framework\views.py", line 463, in handle_exception
    exception_handler = self.get_exception_handler()
  File "C:\Users\USER\AppData\Local\Programs\Python\Python313\Lib\site-packages\rest_framework\views.py", line 298, in get_exception_handler
    return self.settings.EXCEPTION_HANDLER
           ^^^^^^^^^^^^^^^^^^^^^^^^^^^^^^^
  File "C:\Users\USER\AppData\Local\Programs\Python\Python313\Lib\site-packages\rest_framework\settings.py", line 227, in __getattr__
    val = perform_import(val, attr)
  File "C:\Users\USER\AppData\Local\Programs\Python\Python313\Lib\site-packages\rest_framework\settings.py", line 168, in perform_import
    return import_from_string(val, setting_name)
  File "C:\Users\USER\AppData\Local\Programs\Python\Python313\Lib\site-packages\rest_framework\settings.py", line 182, in import_from_string
    raise ImportError(msg)
ImportError: Could not import 'inventory_automation.middleware.custom_exception_handler' for API setting 'EXCEPTION_HANDLER'. ImportError: Module "inventory_automation.middleware" does not define a "custom_exception_handler" attribute/class.
"GET /api/inventory/ HTTP/1.1" 500 138853
Internal Server Error: /api/get-inventory/
Traceback (most recent call last):
  File "C:\Users\USER\AppData\Local\Programs\Python\Python313\Lib\site-packages\rest_framework\views.py", line 497, in dispatch
    self.initial(request, *args, **kwargs)
    ~~~~~~~~~~~~^^^^^^^^^^^^^^^^^^^^^^^^^^
  File "C:\Users\USER\AppData\Local\Programs\Python\Python313\Lib\site-packages\rest_framework\views.py", line 415, in initial
    self.check_permissions(request)
    ~~~~~~~~~~~~~~~~~~~~~~^^^^^^^^^
  File "C:\Users\USER\AppData\Local\Programs\Python\Python313\Lib\site-packages\rest_framework\views.py", line 333, in check_permissions
    self.permission_denied(
    ~~~~~~~~~~~~~~~~~~~~~~^
        request,
        ^^^^^^^^
        message=getattr(permission, 'message', None),
        ^^^^^^^^^^^^^^^^^^^^^^^^^^^^^^^^^^^^^^^^^^^^^
        code=getattr(permission, 'code', None)
        ^^^^^^^^^^^^^^^^^^^^^^^^^^^^^^^^^^^^^^
    )
    ^
  File "C:\Users\USER\AppData\Local\Programs\Python\Python313\Lib\site-packages\rest_framework\views.py", line 174, in permission_denied
    raise exceptions.NotAuthenticated()
rest_framework.exceptions.NotAuthenticated: Authentication credentials were not provided.

During handling of the above exception, another exception occurred:

Traceback (most recent call last):
  File "C:\Users\USER\AppData\Local\Programs\Python\Python313\Lib\site-packages\django\utils\module_loading.py", line 30, in import_string
    return cached_import(module_path, class_name)
  File "C:\Users\USER\AppData\Local\Programs\Python\Python313\Lib\site-packages\django\utils\module_loading.py", line 16, in cached_import
    return getattr(module, class_name)
AttributeError: module 'inventory_automation.middleware' has no attribute 'custom_exception_handler'

The above exception was the direct cause of the following exception:

Traceback (most recent call last):
  File "C:\Users\USER\AppData\Local\Programs\Python\Python313\Lib\site-packages\rest_framework\settings.py", line 179, in import_from_string
    return import_string(val)
  File "C:\Users\USER\AppData\Local\Programs\Python\Python313\Lib\site-packages\django\utils\module_loading.py", line 32, in import_string
    raise ImportError(
    ...<2 lines>...
    ) from err
ImportError: Module "inventory_automation.middleware" does not define a "custom_exception_handler" attribute/class

During handling of the above exception, another exception occurred:

Traceback (most recent call last):
  File "C:\Users\USER\AppData\Local\Programs\Python\Python313\Lib\site-packages\django\core\handlers\exception.py", line 55, in inner
    response = get_response(request)
  File "C:\Users\USER\AppData\Local\Programs\Python\Python313\Lib\site-packages\django\core\handlers\base.py", line 197, in _get_response
    response = wrapped_callback(request, *callback_args, **callback_kwargs)
  File "C:\Users\USER\AppData\Local\Programs\Python\Python313\Lib\site-packages\django\views\decorators\csrf.py", line 65, in _view_wrapper
    return view_func(request, *args, **kwargs)
  File "C:\Users\USER\AppData\Local\Programs\Python\Python313\Lib\site-packages\django\views\generic\base.py", line 104, in view
    return self.dispatch(request, *args, **kwargs)
           ~~~~~~~~~~~~~^^^^^^^^^^^^^^^^^^^^^^^^^^
  File "C:\Users\USER\AppData\Local\Programs\Python\Python313\Lib\site-packages\rest_framework\views.py", line 509, in dispatch
    response = self.handle_exception(exc)
  File "C:\Users\USER\AppData\Local\Programs\Python\Python313\Lib\site-packages\rest_framework\views.py", line 463, in handle_exception
    exception_handler = self.get_exception_handler()
  File "C:\Users\USER\AppData\Local\Programs\Python\Python313\Lib\site-packages\rest_framework\views.py", line 298, in get_exception_handler
    return self.settings.EXCEPTION_HANDLER
           ^^^^^^^^^^^^^^^^^^^^^^^^^^^^^^^
  File "C:\Users\USER\AppData\Local\Programs\Python\Python313\Lib\site-packages\rest_framework\settings.py", line 227, in __getattr__
    val = perform_import(val, attr)
  File "C:\Users\USER\AppData\Local\Programs\Python\Python313\Lib\site-packages\rest_framework\settings.py", line 168, in perform_import
    return import_from_string(val, setting_name)
  File "C:\Users\USER\AppData\Local\Programs\Python\Python313\Lib\site-packages\rest_framework\settings.py", line 182, in import_from_string
    raise ImportError(msg)
ImportError: Could not import 'inventory_automation.middleware.custom_exception_handler' for API setting 'EXCEPTION_HANDLER'. ImportError: Module "inventory_automation.middleware" does not define a "custom_exception_handler" attribute/class.
"GET /api/get-inventory/ HTTP/1.1" 500 139108
